<?xml version="1.0" ?>
<robot name="stickman">

  <!-- Torso (base link) -->
  <link name="torso">
    <inertial>
      <mass value="5.0"/>
      <origin xyz="0 0 0" />
      <inertia ixx="0.1" iyy="0.1" izz="0.1" ixy="0" ixz="0" iyz="0"/>
    </inertial>
    <visual>
      <geometry>
        <box size="0.2 0.1 0.4" />
      </geometry>
      <material name="gray">
        <color rgba="0.5 0.5 0.5 1"/>
      </material>
    </visual>
    <collision>
      <geometry>
        <box size="0.2 0.1 0.4" />
      </geometry>
    </collision>
  </link>

  <!-- Left thigh -->
  <link name="left_thigh">
    <inertial>
      <mass value="2.0"/>
      <origin xyz="0 0 -0.2" />
      <inertia ixx="0.05" iyy="0.05" izz="0.05" ixy="0" ixz="0" iyz="0"/>
    </inertial>
    <visual>
      <geometry>
        <cylinder radius="0.04" length="0.4"/>
      </geometry>
      <material name="blue">
        <color rgba="0 0 1 1"/>
      </material>
    </visual>
    <collision>
      <geometry>
        <cylinder radius="0.04" length="0.4"/>
      </geometry>
    </collision>
  </link>

  <!-- Left shin -->
  <link name="left_shin">
    <inertial>
      <mass value="1.5"/>
      <origin xyz="0 0 -0.2" />
      <inertia ixx="0.03" iyy="0.03" izz="0.03" ixy="0" ixz="0" iyz="0"/>
    </inertial>
    <visual>
      <geometry>
        <cylinder radius="0.035" length="0.4"/>
      </geometry>
      <material name="cyan">
        <color rgba="0 1 1 1"/>
      </material>
    </visual>
    <collision>
      <geometry>
        <cylinder radius="0.035" length="0.4"/>
      </geometry>
    </collision>
  </link>

  <!-- Right thigh -->
  <link name="right_thigh">
    <inertial>
      <mass value="2.0"/>
      <origin xyz="0 0 -0.2" />
      <inertia ixx="0.05" iyy="0.05" izz="0.05" ixy="0" ixz="0" iyz="0"/>
    </inertial>
    <visual>
      <geometry>
        <cylinder radius="0.04" length="0.4"/>
      </geometry>
      <material name="red">
        <color rgba="1 0 0 1"/>
      </material>
    </visual>
    <collision>
      <geometry>
        <cylinder radius="0.04" length="0.4"/>
      </geometry>
    </collision>
  </link>

  <!-- Right shin -->
  <link name="right_shin">
    <inertial>
      <mass value="1.5"/>
      <origin xyz="0 0 -0.2" />
      <inertia ixx="0.03" iyy="0.03" izz="0.03" ixy="0" ixz="0" iyz="0"/>
    </inertial>
    <visual>
      <geometry>
        <cylinder radius="0.035" length="0.4"/>
      </geometry>
      <material name="magenta">
        <color rgba="1 0 1 1"/>
      </material>
    </visual>
    <collision>
      <geometry>
        <cylinder radius="0.035" length="0.4"/>
      </geometry>
    </collision>
  </link>

  <!-- Joints -->
  <joint name="left_hip" type="revolute">
    <parent link="torso"/>
    <child link="left_thigh"/>
    <origin xyz="0.1 0 -0.2" rpy="0 0 0"/>  <!-- ðŸ‘ˆ å®‰å®šæ€§å‘ä¸Šã®ãŸã‚ã«å·¦å³ã«åºƒã’ãŸ -->
    <axis xyz="1 0 0"/>
    <limit lower="-1.5" upper="1.5" effort="50" velocity="2"/>
  </joint>

  <joint name="left_knee" type="revolute">
    <parent link="left_thigh"/>
    <child link="left_shin"/>
    <origin xyz="0 0 -0.4" rpy="0 0 0"/>
    <axis xyz="1 0 0"/>
    <limit lower="0" upper="2.0" effort="50" velocity="2"/>
  </joint>

  <joint name="right_hip" type="revolute">
    <parent link="torso"/>
    <child link="right_thigh"/>
    <origin xyz="-0.1 0 -0.2" rpy="0 0 0"/> <!-- ðŸ‘ˆ å®‰å®šæ€§å‘ä¸Šã®ãŸã‚ã«å·¦å³ã«åºƒã’ãŸ -->
    <axis xyz="1 0 0"/>
    <limit lower="-1.5" upper="1.5" effort="50" velocity="2"/>
  </joint>

  <joint name="right_knee" type="revolute">
    <parent link="right_thigh"/>
    <child link="right_shin"/>
    <origin xyz="0 0 -0.4" rpy="0 0 0"/>
    <axis xyz="1 0 0"/>
    <limit lower="0" upper="2.0" effort="50" velocity="2"/>
  </joint>

</robot>

